<?xml version="1.0"?>
<robot name="starq" xmlns:xacro="http://ros.org/wiki/xacro">

<xacro:property name="base_length" value="0.40"/>
<xacro:property name="base_width" value ="0.25"/>
<xacro:property name="base_height" value="0.086"/>

<xacro:property name="hip_xoff" value="0.165"/>
<xacro:property name="hip_yoff" value="${0.5*base_width}"/>

<xacro:property name="leg_link1_length" value="0.050"/>
<xacro:property name="leg_link2_length" value="0.150"/>

<xacro:property name="leg_link1_width" value="0.005"/>
<xacro:property name="leg_link2_width" value="0.005"/>

<xacro:property name="leg_link1_height" value="0.015"/>
<xacro:property name="leg_link2_height" value="0.015"/>

<xacro:property name="toe_radius" value="0.02"/>

  <!-- Define intertial property macros  -->
  <xacro:macro name="box_inertia" params="m w h d">
    <inertial>
      <origin xyz="0 0 0" rpy="${pi/2} 0 ${pi/2}"/>
      <mass value="${m}"/>
      <inertia ixx="${(m/12) * (h*h + d*d)}" ixy="0.0" ixz="0.0" iyy="${(m/12) * (w*w + d*d)}" iyz="0.0" izz="${(m/12) * (w*w + h*h)}"/>
    </inertial>
  </xacro:macro>

  <xacro:macro name="cylinder_inertia" params="m r h">
    <inertial>
      <origin xyz="0 0 0" rpy="${pi/2} 0 0" />
      <mass value="${m}"/>
      <inertia ixx="${(m/12) * (3*r*r + h*h)}" ixy = "0" ixz = "0" iyy="${(m/12) * (3*r*r + h*h)}" iyz = "0" izz="${(m/2) * (r*r)}"/>
    </inertial>
  </xacro:macro>

  <xacro:macro name="sphere_inertia" params="m r">
    <inertial>
      <mass value="${m}"/>
      <inertia ixx="${(2/5) * m * (r*r)}" ixy="0.0" ixz="0.0" iyy="${(2/5) * m * (r*r)}" iyz="0.0" izz="${(2/5) * m * (r*r)}"/>
    </inertial>
  </xacro:macro>

<!-- Robot Base -->
<link name="base_link">
    <visual>
        <geometry>
            <box size="${base_length} ${base_width} ${base_height}"/>   
        </geometry>
        <material name="Cyan">
            <color rgba="0 1.0 1.0 1.0"/>
        </material>  
    </visual>
    <collision>
        <geometry>
            <box size="${base_length} ${base_width} ${base_height}"/>
        </geometry>
    </collision>
    <xacro:box_inertia m="7.5" w="${base_width}" d="${base_length}" h="${base_height}"/>
</link>

<!-- Robot Footprint -->
<link name="base_footprint"/>
<joint name="base_joint" type="fixed">
    <parent link="base_link"/>
    <child link="base_footprint"/>
    <origin xyz="0 0 ${-(leg_link1_length+leg_link2_length)}"/>
</joint>

<!-- Legs -->
<xacro:macro name="leg" params="prefix x_reflect y_reflect">
    <link name="${prefix}_link1">
        <visual>
            <origin xyz="${0.5*leg_link1_length} 0 0"/>
            <geometry>
                <box size="${leg_link1_length} ${leg_link1_width} ${leg_link1_height}"/>    
            </geometry>
            <material name="Gray">
                <color rgba="0.5 0.5 0.5 1.0"/>
            </material>
        </visual>
        <collision>
            <geometry>
                <box size="${leg_link1_length} ${leg_link1_width} ${leg_link1_height}"/>
            </geometry>
        </collision>
        <xacro:box_inertia m="0.15" w="${leg_link1_width}" d="${leg_link1_length}" h="${leg_link1_height}"/>
    </link>
    <link name="${prefix}_link2">
        <visual>
            <origin xyz="${0.5*leg_link2_length} 0 0"/>
            <geometry>
                <box size="${leg_link2_length} ${leg_link2_width} ${leg_link2_height}"/>    
            </geometry>
            <material name="Gray">
                <color rgba="0.5 0.5 0.5 1.0"/>
            </material>
        </visual>
        <collision>
            <geometry>
                <box size="${leg_link2_length} ${leg_link2_width} ${leg_link2_height}"/>
            </geometry>
        </collision>
        <xacro:box_inertia m="0.15" w="${leg_link2_width}" d="${leg_link2_length}" h="${leg_link2_height}"/>
    </link>
    <link name="${prefix}_toe">
        <visual>
            <geometry>
                <sphere radius="${toe_radius}"/>
            </geometry>
            <material name="Yellow">
                <color rgba="1.0 1.0 0.0 1.0"/>
            </material>
        </visual>
        <collision>
            <geometry>
                <sphere radius="${toe_radius}"/>
            </geometry>
        </collision>
        <xacro:sphere_inertia m="0.10" r="${toe_radius}"/>
    </link>
    <joint name="${prefix}_hip_joint" type="continuous">
        <parent link="base_link"/>
        <child link="${prefix}_link1"/>
        <origin xyz="${x_reflect*hip_xoff} ${y_reflect*hip_yoff + 0.5*y_reflect*leg_link1_width} 0"/>
        <axis xyz="0 1 0"/>
    </joint>
        <joint name="${prefix}_leg_link_joint" type="continuous">
        <parent link="${prefix}_link1"/>
        <child link="${prefix}_link2"/>
        <origin xyz="${leg_link1_length} 0 0"/>
        <axis xyz="0 1 0"/>
    </joint>
    <joint name="${prefix}_toe_joint" type="fixed">
        <parent link="${prefix}_link2"/>
        <child link="${prefix}_toe"/>
        <origin xyz="${leg_link2_length} 0 0"/>
        <dynamics damping="0.7"/>
    </joint>
</xacro:macro>

<xacro:leg prefix="leg_fr" x_reflect="1" y_reflect="1"/>
<xacro:leg prefix="leg_fl" x_reflect="1" y_reflect="-1"/>
<xacro:leg prefix="leg_hr" x_reflect="-1" y_reflect="1"/>
<xacro:leg prefix="leg_hl" x_reflect="-1" y_reflect="-1"/>

<xacro:macro name="joint_control" params="name">
    <joint name="${name}_hip_joint">
        <command_interface name="position"/>
        <state_interface name="position">
            <param name="initial_value">1.0</param>
        </state_interface>
        <state_interface name="velocity"/>
    </joint>
    <joint name="${name}_leg_link_joint">
        <command_interface name="position"/>
        <state_interface name="position">
            <param name="initial_value">1.0</param>
        </state_interface>
        <state_interface name="velocity"/>
    </joint>
</xacro:macro>

<ros2_control name="GazeboSystem" type="system">
    <hardware>
        <plugin>gazebo_ros2_control/GazeboSystem</plugin>
    </hardware>
    <xacro:joint_control name="leg_fr"/>
    <xacro:joint_control name="leg_fl"/>
    <xacro:joint_control name="leg_hr"/>
    <xacro:joint_control name="leg_hl"/>
</ros2_control>

<gazebo>
    <plugin filename="libgazebo_ros2_control.so" name="gazebo_ros2_control">
        <parameters>$(find starq_description)/config/controllers.yaml</parameters>
    </plugin>
</gazebo>

</robot>